Traceback (most recent call last):
  File "C:\Users\Admin\Desktop\RWE+\LevelProcess.py", line 121, in mainprocessupdate
    self.mainprocess.update()
  File "C:\Users\Admin\Desktop\RWE+\LevelProcess.py", line 528, in update
    self.doevents()
  File "C:\Users\Admin\Desktop\RWE+\LevelProcess.py", line 516, in doevents
    self.keypress()
  File "C:\Users\Admin\Desktop\RWE+\LevelProcess.py", line 489, in keypress
    self.menu.send(pressed)
  File "C:\Users\Admin\Desktop\RWE+\menuclass.py", line 795, in send
    super().send(message)
  File "C:\Users\Admin\Desktop\RWE+\menuclass.py", line 544, in send
    getattr(self, message[1:])()
  File "C:\Users\Admin\Desktop\RWE+\PE.py", line 432, in cat_next_propupdate
    self.cat_next()
  File "C:\Users\Admin\Desktop\RWE+\PE.py", line 438, in cat_next
    self.selector.right()
  File "C:\Users\Admin\Desktop\RWE+\widgets.py", line 771, in right
    self.onclick("set")
  File "C:\Users\Admin\Desktop\RWE+\widgets.py", line 692, in onclick
    self.callback(self.selecteditem)
                  ^^^^^^^^^^^^^^^^^
  File "C:\Users\Admin\Desktop\RWE+\widgets.py", line 830, in selecteditem
    return self.data[self.currentcategory]["items"][self.currentitem]
           ~~~~~~~~~~~~~~~~~~~~~~~~~~~~~~~~~~~~~~~~^^^^^^^^^^^^^^^^^^
IndexError: list index out of range
This is why RWE+ crashed^^^
Sorry